Workbook

Sheet LogVsRegistre
A1: ID_Antenne | B1: Province_RDC | C1: Latitude | D1: Longitude | E1: Technologie | F1: Equipementier | G1: Nbre_Abonnés_Impactés | H1: Durée_Total_panne_Min
A2: ANT-0001 | B2: Nord-Ubangi | C2: -8.143791 | D2: 28.946161 | E2: 4G | F2: ZTE | G2: =IFERROR(_xlfn.XLOOKUP([1]!Registre[[#This Row],[ID_Antenne]],[1]Log_Réseaux!B:B,[1]Log_Réseaux!C:C),"NA") -> 5 | H2: =IFERROR(_xlfn.XLOOKUP([1]!Registre[[#This Row],[ID_Antenne]],[1]Log_Réseaux!B:B,[1]Log_Réseaux!D:D),"NA") -> 252
A3: ANT-0002 | B3: Mai-Ndombe | C3: -10.442425 | D3: 23.243632 | E3: 4G | F3: Nokia | G3: =IFERROR(_xlfn.XLOOKUP([1]!Registre[[#This Row],[ID_Antenne]],[1]Log_Réseaux!B:B,[1]Log_Réseaux!C:C),"NA") -> 6 | H3: =IFERROR(_xlfn.XLOOKUP([1]!Registre[[#This Row],[ID_Antenne]],[1]Log_Réseaux!B:B,[1]Log_Réseaux!D:D),"NA") -> 356
A4: ANT-0005 | B4: Equateur | C4: -3.544581 | D4: 14.776605 | E4: 4G | F4: Nokia | G4: =IFERROR(_xlfn.XLOOKUP([1]!Registre[[#This Row],[ID_Antenne]],[1]Log_Réseaux!B:B,[1]Log_Réseaux!C:C),"NA") -> 6 | H4: =IFERROR(_xlfn.XLOOKUP([1]!Registre[[#This Row],[ID_Antenne]],[1]Log_Réseaux!B:B,[1]Log_Réseaux!D:D),"NA") -> 281
A5: ANT-0006 | B5: Bas-Uele | C5: -2.853287 | D5: 22.117896 | E5: 5G | F5: Huawei | G5: =IFERROR(_xlfn.XLOOKUP([1]!Registre[[#This Row],[ID_Antenne]],[1]Log_Réseaux!B:B,[1]Log_Réseaux!C:C),"NA") -> 3 | H5: =IFERROR(_xlfn.XLOOKUP([1]!Registre[[#This Row],[ID_Antenne]],[1]Log_Réseaux!B:B,[1]Log_Réseaux!D:D),"NA") -> 132
A6: ANT-0007 | B6: Tshopo | C6: 4.777735 | D6: 16.392204 | E6: 5G | F6: ZTE | G6: =IFERROR(_xlfn.XLOOKUP([1]!Registre[[#This Row],[ID_Antenne]],[1]Log_Réseaux!B:B,[1]Log_Réseaux!C:C),"NA") -> 4 | H6: =IFERROR(_xlfn.XLOOKUP([1]!Registre[[#This Row],[ID_Antenne]],[1]Log_Réseaux!B:B,[1]Log_Réseaux!D:D),"NA") -> 250
A7: ANT-0008 | B7: Haut-Lomami | C7: -11.89448 | D7: 19.216215 | E7: 3G | F7: ZTE | G7: =IFERROR(_xlfn.XLOOKUP([1]!Registre[[#This Row],[ID_Antenne]],[1]Log_Réseaux!B:B,[1]Log_Réseaux!C:C),"NA") -> 4 | H7: =IFERROR(_xlfn.XLOOKUP([1]!Registre[[#This Row],[ID_Antenne]],[1]Log_Réseaux!B:B,[1]Log_Réseaux!D:D),"NA") -> 203
A8: ANT-0010 | B8: Haut-Katanga | C8: 4.471256 | D8: 27.107028 | E8: 3G | F8: Ericsson | G8: =IFERROR(_xlfn.XLOOKUP([1]!Registre[[#This Row],[ID_Antenne]],[1]Log_Réseaux!B:B,[1]Log_Réseaux!C:C),"NA") -> 3 | H8: =IFERROR(_xlfn.XLOOKUP([1]!Registre[[#This Row],[ID_Antenne]],[1]Log_Réseaux!B:B,[1]Log_Réseaux!D:D),"NA") -> 230
A9: ANT-0011 | B9: Mai-Ndombe | C9: -1.607639 | D9: 17.003636 | E9: 4G | F9: Ericsson | G9: =IFERROR(_xlfn.XLOOKUP([1]!Registre[[#This Row],[ID_Antenne]],[1]Log_Réseaux!B:B,[1]Log_Réseaux!C:C),"NA") -> 4 | H9: =IFERROR(_xlfn.XLOOKUP([1]!Registre[[#This Row],[ID_Antenne]],[1]Log_Réseaux!B:B,[1]Log_Réseaux!D:D),"NA") -> 208
A10: ANT-0016 | B10: Kongo-Central | C10: 2.983602 | D10: 21.893065 | E10: 5G | F10: Nokia | G10: =IFERROR(_xlfn.XLOOKUP([1]!Registre[[#This Row],[ID_Antenne]],[1]Log_Réseaux!B:B,[1]Log_Réseaux!C:C),"NA") -> 4 | H10: =IFERROR(_xlfn.XLOOKUP([1]!Registre[[#This Row],[ID_Antenne]],[1]Log_Réseaux!B:B,[1]Log_Réseaux!D:D),"NA") -> 283
A11: ANT-0017 | B11: Sankuru | C11: -3.419035 | D11: 29.018316 | E11: 5G | F11: Ericsson | G11: =IFERROR(_xlfn.XLOOKUP([1]!Registre[[#This Row],[ID_Antenne]],[1]Log_Réseaux!B:B,[1]Log_Réseaux!C:C),"NA") -> 3 | H11: =IFERROR(_xlfn.XLOOKUP([1]!Registre[[#This Row],[ID_Antenne]],[1]Log_Réseaux!B:B,[1]Log_Réseaux!D:D),"NA") -> 254
A12: ANT-0020 | B12: Kasai | C12: -10.059846 | D12: 14.375758 | E12: 4G | F12: Huawei | G12: =IFERROR(_xlfn.XLOOKUP([1]!Registre[[#This Row],[ID_Antenne]],[1]Log_Réseaux!B:B,[1]Log_Réseaux!C:C),"NA") -> 6 | H12: =IFERROR(_xlfn.XLOOKUP([1]!Registre[[#This Row],[ID_Antenne]],[1]Log_Réseaux!B:B,[1]Log_Réseaux!D:D),"NA") -> 340
A13: ANT-0023 | B13: Haut-Lomami | C13: -9.780186 | D13: 16.64955 | E13: 5G | F13: Ericsson | G13: =IFERROR(_xlfn.XLOOKUP([1]!Registre[[#This Row],[ID_Antenne]],[1]Log_Réseaux!B:B,[1]Log_Réseaux!C:C),"NA") -> 2 | H13: =IFERROR(_xlfn.XLOOKUP([1]!Registre[[#This Row],[ID_Antenne]],[1]Log_Réseaux!B:B,[1]Log_Réseaux!D:D),"NA") -> 153
... A74: ANT-0159 | B74: Sud-Kivu | C74: 2.441451 | D74: 30.167489 | E74: 5G | F74: Nokia | G74: =IFERROR(_xlfn.XLOOKUP([1]!Registre[[#This Row],[ID_Antenne]],[1]Log_Réseaux!B:B,[1]Log_Réseaux!C:C),"NA") -> 8 | H74: =IFERROR(_xlfn.XLOOKUP([1]!Registre[[#This Row],[ID_Antenne]],[1]Log_Réseaux!B:B,[1]Log_Réseaux!D:D),"NA") -> 562
A75: ANT-0160 | C75: -8.487583 | D75: 19.436312 | E75: 5G | F75: Huawei | G75: =IFERROR(_xlfn.XLOOKUP([1]!Registre[[#This Row],[ID_Antenne]],[1]Log_Réseaux!B:B,[1]Log_Réseaux!C:C),"NA") -> NA | H75: =IFERROR(_xlfn.XLOOKUP([1]!Registre[[#This Row],[ID_Antenne]],[1]Log_Réseaux!B:B,[1]Log_Réseaux!D:D),"NA") -> NA
A76: ANT-0162 | B76: Kasai-Oriental | C76: -1.648326 | D76: 25.528902 | E76: 4G | F76: Huawei | G76: =IFERROR(_xlfn.XLOOKUP([1]!Registre[[#This Row],[ID_Antenne]],[1]Log_Réseaux!B:B,[1]Log_Réseaux!C:C),"NA") -> 3 | H76: =IFERROR(_xlfn.XLOOKUP([1]!Registre[[#This Row],[ID_Antenne]],[1]Log_Réseaux!B:B,[1]Log_Réseaux!D:D),"NA") -> 105
A77: ANT-0164 | B77: Kinshasa | C77: -11.389362 | D77: 22.240174 | E77: 5G | F77: ZTE | G77: =IFERROR(_xlfn.XLOOKUP([1]!Registre[[#This Row],[ID_Antenne]],[1]Log_Réseaux!B:B,[1]Log_Réseaux!C:C),"NA") -> 8 | H77: =IFERROR(_xlfn.XLOOKUP([1]!Registre[[#This Row],[ID_Antenne]],[1]Log_Réseaux!B:B,[1]Log_Réseaux!D:D),"NA") -> 461
A78: ANT-0165 | B78: Sud-Ubangi | C78: -0.549086 | D78: 14.816867 | E78: 5G | F78: ZTE | G78: =IFERROR(_xlfn.XLOOKUP([1]!Registre[[#This Row],[ID_Antenne]],[1]Log_Réseaux!B:B,[1]Log_Réseaux!C:C),"NA") -> 5 | H78: =IFERROR(_xlfn.XLOOKUP([1]!Registre[[#This Row],[ID_Antenne]],[1]Log_Réseaux!B:B,[1]Log_Réseaux!D:D),"NA") -> 296
A79: ANT-0166 | B79: Sud-Ubangi | C79: -10.56448 | D79: 19.792876 | E79: 5G | F79: Ericsson | G79: =IFERROR(_xlfn.XLOOKUP([1]!Registre[[#This Row],[ID_Antenne]],[1]Log_Réseaux!B:B,[1]Log_Réseaux!C:C),"NA") -> 11 | H79: =IFERROR(_xlfn.XLOOKUP([1]!Registre[[#This Row],[ID_Antenne]],[1]Log_Réseaux!B:B,[1]Log_Réseaux!D:D),"NA") -> 456
A80: ANT-0170 | B80: Bas-Uele | C80: -12.244119 | D80: 28.279756 | E80: 5G | F80: ZTE | G80: =IFERROR(_xlfn.XLOOKUP([1]!Registre[[#This Row],[ID_Antenne]],[1]Log_Réseaux!B:B,[1]Log_Réseaux!C:C),"NA") -> 4 | H80: =IFERROR(_xlfn.XLOOKUP([1]!Registre[[#This Row],[ID_Antenne]],[1]Log_Réseaux!B:B,[1]Log_Réseaux!D:D),"NA") -> 255
A81: ANT-0171 | B81: Kwilu | C81: -3.571288 | D81: 12.931596 | E81: 4G | F81: Nokia | G81: =IFERROR(_xlfn.XLOOKUP([1]!Registre[[#This Row],[ID_Antenne]],[1]Log_Réseaux!B:B,[1]Log_Réseaux!C:C),"NA") -> 2 | H81: =IFERROR(_xlfn.XLOOKUP([1]!Registre[[#This Row],[ID_Antenne]],[1]Log_Réseaux!B:B,[1]Log_Réseaux!D:D),"NA") -> 137
A82: ANT-0172 | B82: Lualaba | C82: 2.266232 | D82: 29.532896 | E82: 4G | F82: Ericsson | G82: =IFERROR(_xlfn.XLOOKUP([1]!Registre[[#This Row],[ID_Antenne]],[1]Log_Réseaux!B:B,[1]Log_Réseaux!C:C),"NA") -> 4 | H82: =IFERROR(_xlfn.XLOOKUP([1]!Registre[[#This Row],[ID_Antenne]],[1]Log_Réseaux!B:B,[1]Log_Réseaux!D:D),"NA") -> 221
A83: ANT-0174 | B83: Maniema | C83: 3.08182 | D83: 29.961941 | E83: 4G | F83: Huawei | G83: =IFERROR(_xlfn.XLOOKUP([1]!Registre[[#This Row],[ID_Antenne]],[1]Log_Réseaux!B:B,[1]Log_Réseaux!C:C),"NA") -> 5 | H83: =IFERROR(_xlfn.XLOOKUP([1]!Registre[[#This Row],[ID_Antenne]],[1]Log_Réseaux!B:B,[1]Log_Réseaux!D:D),"NA") -> 314
A84: ANT-0175 | B84: Maniema | C84: 0.850665 | D84: 19.446418 | E84: 4G | F84: Huawei | G84: =IFERROR(_xlfn.XLOOKUP([1]!Registre[[#This Row],[ID_Antenne]],[1]Log_Réseaux!B:B,[1]Log_Réseaux!C:C),"NA") -> 3 | H84: =IFERROR(_xlfn.XLOOKUP([1]!Registre[[#This Row],[ID_Antenne]],[1]Log_Réseaux!B:B,[1]Log_Réseaux!D:D),"NA") -> 164
A85: ANT-0178 | B85: Kasai | C85: 4.146449 | D85: 17.793337 | E85: 5G | F85: ZTE | G85: =IFERROR(_xlfn.XLOOKUP([1]!Registre[[#This Row],[ID_Antenne]],[1]Log_Réseaux!B:B,[1]Log_Réseaux!C:C),"NA") -> 7 | H85: =IFERROR(_xlfn.XLOOKUP([1]!Registre[[#This Row],[ID_Antenne]],[1]Log_Réseaux!B:B,[1]Log_Réseaux!D:D),"NA") -> 434
A86: ANT-0179 | B86: Nord-Kivu | C86: 0.928852 | D86: 25.868548 | E86: 5G | F86: Nokia | G86: =IFERROR(_xlfn.XLOOKUP([1]!Registre[[#This Row],[ID_Antenne]],[1]Log_Réseaux!B:B,[1]Log_Réseaux!C:C),"NA") -> 5 | H86: =IFERROR(_xlfn.XLOOKUP([1]!Registre[[#This Row],[ID_Antenne]],[1]Log_Réseaux!B:B,[1]Log_Réseaux!D:D),"NA") -> 328
A87: ANT-0180 | B87: Tshopo | C87: 2.442598 | D87: 24.924308 | E87: 5G | F87: Ericsson | G87: =IFERROR(_xlfn.XLOOKUP([1]!Registre[[#This Row],[ID_Antenne]],[1]Log_Réseaux!B:B,[1]Log_Réseaux!C:C),"NA") -> 5 | H87: =IFERROR(_xlfn.XLOOKUP([1]!Registre[[#This Row],[ID_Antenne]],[1]Log_Réseaux!B:B,[1]Log_Réseaux!D:D),"NA") -> 229
... A301: ANT-0614 | B301: Tshopo | C301: -6.183785 | D301: 25.138759 | E301: 3G | F301: Ericsson | G301: =IFERROR(_xlfn.XLOOKUP([1]!Registre[[#This Row],[ID_Antenne]],[1]Log_Réseaux!B:B,[1]Log_Réseaux!C:C),"NA") -> 1 | H301: =IFERROR(_xlfn.XLOOKUP([1]!Registre[[#This Row],[ID_Antenne]],[1]Log_Réseaux!B:B,[1]Log_Réseaux!D:D),"NA") -> 115
A302: ANT-0615 | C302: 3.979001 | D302: 28.069559 | E302: 3G | F302: Huawei | G302: =IFERROR(_xlfn.XLOOKUP([1]!Registre[[#This Row],[ID_Antenne]],[1]Log_Réseaux!B:B,[1]Log_Réseaux!C:C),"NA") -> 1 | H302: =IFERROR(_xlfn.XLOOKUP([1]!Registre[[#This Row],[ID_Antenne]],[1]Log_Réseaux!B:B,[1]Log_Réseaux!D:D),"NA") -> 68
A303: ANT-0616 | B303: Equateur | C303: -3.709361 | D303: 23.959943 | E303: 4G | F303: Huawei | G303: =IFERROR(_xlfn.XLOOKUP([1]!Registre[[#This Row],[ID_Antenne]],[1]Log_Réseaux!B:B,[1]Log_Réseaux!C:C),"NA") -> NA | H303: =IFERROR(_xlfn.XLOOKUP([1]!Registre[[#This Row],[ID_Antenne]],[1]Log_Réseaux!B:B,[1]Log_Réseaux!D:D),"NA") -> NA
A304: ANT-0617 | B304: Tshuapa | C304: -7.758771 | D304: 17.880848 | E304: 3G | F304: Ericsson | G304: =IFERROR(_xlfn.XLOOKUP([1]!Registre[[#This Row],[ID_Antenne]],[1]Log_Réseaux!B:B,[1]Log_Réseaux!C:C),"NA") -> 1 | H304: =IFERROR(_xlfn.XLOOKUP([1]!Registre[[#This Row],[ID_Antenne]],[1]Log_Réseaux!B:B,[1]Log_Réseaux!D:D),"NA") -> 50
A305: ANT-0618 | B305: Mongala | C305: -4.332408 | D305: 14.119439 | E305: 5G | F305: Nokia | G305: =IFERROR(_xlfn.XLOOKUP([1]!Registre[[#This Row],[ID_Antenne]],[1]Log_Réseaux!B:B,[1]Log_Réseaux!C:C),"NA") -> NA | H305: =IFERROR(_xlfn.XLOOKUP([1]!Registre[[#This Row],[ID_Antenne]],[1]Log_Réseaux!B:B,[1]Log_Réseaux!D:D),"NA") -> NA
A306: ANT-0619 | B306: Sankuru | C306: -7.513261 | D306: 24.338812 | E306: 5G | F306: Huawei | G306: =IFERROR(_xlfn.XLOOKUP([1]!Registre[[#This Row],[ID_Antenne]],[1]Log_Réseaux!B:B,[1]Log_Réseaux!C:C),"NA") -> 1 | H306: =IFERROR(_xlfn.XLOOKUP([1]!Registre[[#This Row],[ID_Antenne]],[1]Log_Réseaux!B:B,[1]Log_Réseaux!D:D),"NA") -> 46
A307: ANT-0620 | B307: Nord-Kivu | C307: -4.175494 | D307: 16.704665 | E307: 3G | F307: Ericsson | G307: =IFERROR(_xlfn.XLOOKUP([1]!Registre[[#This Row],[ID_Antenne]],[1]Log_Réseaux!B:B,[1]Log_Réseaux!C:C),"NA") -> 2 | H307: =IFERROR(_xlfn.XLOOKUP([1]!Registre[[#This Row],[ID_Antenne]],[1]Log_Réseaux!B:B,[1]Log_Réseaux!D:D),"NA") -> 105
A308: ANT-0621 | B308: Haut-Katanga | C308: -2.926736 | D308: 18.170461 | E308: 5G | F308: Ericsson | G308: =IFERROR(_xlfn.XLOOKUP([1]!Registre[[#This Row],[ID_Antenne]],[1]Log_Réseaux!B:B,[1]Log_Réseaux!C:C),"NA") -> 1 | H308: =IFERROR(_xlfn.XLOOKUP([1]!Registre[[#This Row],[ID_Antenne]],[1]Log_Réseaux!B:B,[1]Log_Réseaux!D:D),"NA") -> 53
A309: ANT-0622 | B309: Haut-Uele | C309: -3.003879 | D309: 23.633893 | E309: 5G | F309: Ericsson | G309: =IFERROR(_xlfn.XLOOKUP([1]!Registre[[#This Row],[ID_Antenne]],[1]Log_Réseaux!B:B,[1]Log_Réseaux!C:C),"NA") -> 1 | H309: =IFERROR(_xlfn.XLOOKUP([1]!Registre[[#This Row],[ID_Antenne]],[1]Log_Réseaux!B:B,[1]Log_Réseaux!D:D),"NA") -> 100
A310: ANT-0624 | B310: Haut-Katanga | C310: 0.172153 | D310: 21.091376 | E310: 3G | F310: Ericsson | G310: =IFERROR(_xlfn.XLOOKUP([1]!Registre[[#This Row],[ID_Antenne]],[1]Log_Réseaux!B:B,[1]Log_Réseaux!C:C),"NA") -> 3 | H310: =IFERROR(_xlfn.XLOOKUP([1]!Registre[[#This Row],[ID_Antenne]],[1]Log_Réseaux!B:B,[1]Log_Réseaux!D:D),"NA") -> 165
A311: ANT-0625 | B311: Haut-Lomami | C311: 0.76493 | D311: 21.564275 | E311: 3G | F311: ZTE | G311: =IFERROR(_xlfn.XLOOKUP([1]!Registre[[#This Row],[ID_Antenne]],[1]Log_Réseaux!B:B,[1]Log_Réseaux!C:C),"NA") -> NA | H311: =IFERROR(_xlfn.XLOOKUP([1]!Registre[[#This Row],[ID_Antenne]],[1]Log_Réseaux!B:B,[1]Log_Réseaux!D:D),"NA") -> NA
A312: ANT-0627 | B312: Nord-Ubangi | C312: -11.472475 | D312: 27.4189 | E312: 4G | F312: ZTE | G312: =IFERROR(_xlfn.XLOOKUP([1]!Registre[[#This Row],[ID_Antenne]],[1]Log_Réseaux!B:B,[1]Log_Réseaux!C:C),"NA") -> NA | H312: =IFERROR(_xlfn.XLOOKUP([1]!Registre[[#This Row],[ID_Antenne]],[1]Log_Réseaux!B:B,[1]Log_Réseaux!D:D),"NA") -> NA
A313: ANT-0629 | B313: Kwango | C313: 1.204588 | D313: 15.525152 | E313: 5G | F313: Huawei | G313: =IFERROR(_xlfn.XLOOKUP([1]!Registre[[#This Row],[ID_Antenne]],[1]Log_Réseaux!B:B,[1]Log_Réseaux!C:C),"NA") -> NA | H313: =IFERROR(_xlfn.XLOOKUP([1]!Registre[[#This Row],[ID_Antenne]],[1]Log_Réseaux!B:B,[1]Log_Réseaux!D:D),"NA") -> NA
...

Sheet Synthèse Macroscopique
B3: Étiquettes de colonnes
B4: Moyenne de Nbre_Abonnés_Impactés | E4: Somme de Durée_Total_panne_Min | H4: Total Moyenne de Nbre_Abonnés_Impactés | I4: Total Somme de Durée_Total_panne_Min
A5: Étiquettes de lignes | B5: 3G | C5: 4G | D5: 5G | E5: 3G | F5: 4G | G5: 5G
A6: Bas-Uele | B6: 2.2 | C6: 4.25 | D6: 2.6 | E6: 610 | F6: 1262 | G6: 787 | H6: 2.9285714 | I6: 2659
A7: Equateur | B7: 2.8 | C7: 2.6666667 | D7: 2.8 | E7: 849 | F7: 399 | G7: 997 | H7: 2.7692308 | I7: 2245
A8: Haut-Katanga | B8: 3 | C8: 2.5 | D8: 1.6666667 | E8: 1121 | F8: 696 | G8: 849 | H8: 2.3333333 | I8: 2666
A9: Haut-Lomami | B9: 1.75 | C9: 2.875 | D9: 1.5 | E9: 422 | F9: 1402 | G9: 240 | H9: 2.3571429 | I9: 2064
A10: Haut-Uele | B10: 2 | C10: 2 | D10: 2.625 | E10: 330 | F10: 720 | G10: 1335 | H10: 2.2941176 | I10: 2385
A11: Ituri | B11: 3 | C11: 3 | D11: 2.75 | E11: 910 | F11: 627 | G11: 617 | H11: 2.9090909 | I11: 2154
A12: Kasai | B12: 1.6666667 | C12: 3.3333333 | D12: 3 | E12: 290 | F12: 551 | G12: 1024 | H12: 2.7272727 | I12: 1865
A13: Kasai-Central | B13: 4 | C13: 1.5 | D13: 4.5 | E13: 911 | F13: 488 | G13: 421 | H13: 2.8333333 | I13: 1820
A14: Kasai-Oriental | B14: 1.5 | C14: 2 | D14: 1.8 | E14: 152 | F14: 214 | G14: 564 | H14: 1.7777778 | I14: 930
A15: Kinshasa | B15: 1.8333333 | C15: 1.5 | D15: 2.6666667 | E15: 757 | F15: 174 | G15: 918 | H15: 2.1428571 | I15: 1849
A16: Kongo-Central | B16: 2 | C16: 3.5 | D16: 3.2 | E16: 331 | F16: 812 | G16: 2499 | H16: 3.125 | I16: 3642
A17: Kwango | B17: 3 | C17: 2.4 | D17: 2 | E17: 139 | F17: 680 | G17: 566 | H17: 2.2727273 | I17: 1385
... A21: Mai-Ndombe | B21: 1 | C21: 4.2 | D21: 2 | E21: 139 | F21: 1015 | G21: 89 | H21: 3.125 | I21: 1243
A22: Maniema | B22: #DIV/0! | C22: 3.4444444 | D22: 2.5 | E22: 0 | F22: 1953 | G22: 596 | H22: 3.1538462 | I22: 2549
A23: Mongala | B23: 5 | C23: 1.5 | D23: 1.8 | E23: 714 | F23: 313 | G23: 591 | H23: 2.4444444 | I23: 1618
A24: Nord-Kivu | B24: 2.625 | C24: 2.4 | D24: 3 | E24: 1338 | F24: 564 | G24: 1720 | H24: 2.7391304 | I24: 3622
A25: Nord-Ubangi | B25: 5.5 | C25: 2.8 | D25: 2.8333333 | E25: 530 | F25: 888 | G25: 1074 | H25: 3.2307692 | I25: 2492
A26: Sankuru | B26: 4 | C26: 2.25 | D26: 1.4 | E26: 524 | F26: 530 | G26: 453 | H26: 2.1818182 | I26: 1507
A27: Sud-Kivu | B27: 3.3636364 | C27: 2 | D27: 3 | E27: 2470 | F27: 205 | G27: 960 | H27: 3.1176471 | I27: 3635
A28: Sud-Ubangi | B28: 2.8 | C28: 2 | D28: 5 | E28: 896 | F28: 357 | G28: 1795 | H28: 3.6923077 | I28: 3048
A29: Tanganyika | B29: 2 | C29: 2.6666667 | D29: 1.7777778 | E29: 533 | F29: 1044 | G29: 1079 | H29: 2.1052632 | I29: 2656
A30: Tshopo | B30: 2.5 | C30: 2.8 | D30: 2.6666667 | E30: 724 | F30: 1008 | G30: 903 | H30: 2.6666667 | I30: 2635
A31: Tshuapa | B31: 1.1666667 | C31: 5.5 | D31: 1.6666667 | E31: 360 | F31: 683 | G31: 577 | H31: 2 | I31: 1620
A32: (vide) | B32: 1 | D32: #DIV/0! | E32: 68 | G32: 0 | H32: 1 | I32: 68
A33: Total général | B33: 2.5 | C33: 2.7413793 | D33: 2.5538462 | E33: 16906 | F33: 19610 | G33: 21294 | H33: 2.5994318 | I33: 57810

Sheet Clients
A1: ID_Client | B1: Province_Client | C1: Type_Forfait | D1: Facture_Mensuelle | E1: Ancienneté_Année | F1: Durée_Cumulée_Panne_Heure | G1: Plaintes_Service_Client | H1: Remise | I1: Perte_Financière
A2: CLI-00007 | B2: Tanganyika | C2: Bloqué 5Go | D2: 98.95 | E2: 9 | F2: 2 | G2: 5 | H2: =IF(AND(Clients[[#This Row],[Durée_Cumulée_Panne_Heure]]>12,Clients[[#This Row],[Ancienneté_Année]]>5),"70%",IF(OR(AND(Clients[[#This Row],[Durée_Cumulée_Panne_Heure]]>=4,Clients[[#This Row],[Durée_Cumulée_Panne_Heure]]<=12),AND(Clients[[#This Row],[Ancienneté_Année]]<5,Clients[[#This Row],[Type_Forfait]]="Premium 5G 150Go")),"45%",IF(Clients[[#This Row],[Type_Forfait]]="Pro Monde","10%","0%"))) -> 0% | I2: =Clients[[#This Row],[Facture_Mensuelle]]*Clients[[#This Row],[Remise]] -> 0
A3: CLI-00009 | B3: Kwilu | C3: Pro Monde | D3: 84.66 | E3: 9 | F3: 5 | G3: 2 | H3: =IF(AND(Clients[[#This Row],[Durée_Cumulée_Panne_Heure]]>12,Clients[[#This Row],[Ancienneté_Année]]>5),"70%",IF(OR(AND(Clients[[#This Row],[Durée_Cumulée_Panne_Heure]]>=4,Clients[[#This Row],[Durée_Cumulée_Panne_Heure]]<=12),AND(Clients[[#This Row],[Ancienneté_Année]]<5,Clients[[#This Row],[Type_Forfait]]="Premium 5G 150Go")),"45%",IF(Clients[[#This Row],[Type_Forfait]]="Pro Monde","10%","0%"))) -> 45% | I3: =Clients[[#This Row],[Facture_Mensuelle]]*Clients[[#This Row],[Remise]] -> 38.097
A4: CLI-00011 | B4: Mongala | C4: Illimité 50Go | D4: 65.4 | E4: 4 | F4: 1 | G4: 2 | H4: =IF(AND(Clients[[#This Row],[Durée_Cumulée_Panne_Heure]]>12,Clients[[#This Row],[Ancienneté_Année]]>5),"70%",IF(OR(AND(Clients[[#This Row],[Durée_Cumulée_Panne_Heure]]>=4,Clients[[#This Row],[Durée_Cumulée_Panne_Heure]]<=12),AND(Clients[[#This Row],[Ancienneté_Année]]<5,Clients[[#This Row],[Type_Forfait]]="Premium 5G 150Go")),"45%",IF(Clients[[#This Row],[Type_Forfait]]="Pro Monde","10%","0%"))) -> 0% | I4: =Clients[[#This Row],[Facture_Mensuelle]]*Clients[[#This Row],[Remise]] -> 0
A5: CLI-00012 | B5: Kongo-Central | C5: Illimité 50Go | D5: 15.88 | E5: 9 | F5: 3 | G5: 5 | H5: =IF(AND(Clients[[#This Row],[Durée_Cumulée_Panne_Heure]]>12,Clients[[#This Row],[Ancienneté_Année]]>5),"70%",IF(OR(AND(Clients[[#This Row],[Durée_Cumulée_Panne_Heure]]>=4,Clients[[#This Row],[Durée_Cumulée_Panne_Heure]]<=12),AND(Clients[[#This Row],[Ancienneté_Année]]<5,Clients[[#This Row],[Type_Forfait]]="Premium 5G 150Go")),"45%",IF(Clients[[#This Row],[Type_Forfait]]="Pro Monde","10%","0%"))) -> 0% | I5: =Clients[[#This Row],[Facture_Mensuelle]]*Clients[[#This Row],[Remise]] -> 0
A6: CLI-00017 | B6: Tanganyika | C6: Illimité 50Go | D6: 43.83 | E6: 2 | F6: 2 | G6: 5 | H6: =IF(AND(Clients[[#This Row],[Durée_Cumulée_Panne_Heure]]>12,Clients[[#This Row],[Ancienneté_Année]]>5),"70%",IF(OR(AND(Clients[[#This Row],[Durée_Cumulée_Panne_Heure]]>=4,Clients[[#This Row],[Durée_Cumulée_Panne_Heure]]<=12),AND(Clients[[#This Row],[Ancienneté_Année]]<5,Clients[[#This Row],[Type_Forfait]]="Premium 5G 150Go")),"45%",IF(Clients[[#This Row],[Type_Forfait]]="Pro Monde","10%","0%"))) -> 0% | I6: =Clients[[#This Row],[Facture_Mensuelle]]*Clients[[#This Row],[Remise]] -> 0
A7: CLI-00022 | B7: Haut-Lomami | C7: Premium 5G 150Go | D7: 21.17 | E7: 6 | F7: 8 | G7: 0 | H7: =IF(AND(Clients[[#This Row],[Durée_Cumulée_Panne_Heure]]>12,Clients[[#This Row],[Ancienneté_Année]]>5),"70%",IF(OR(AND(Clients[[#This Row],[Durée_Cumulée_Panne_Heure]]>=4,Clients[[#This Row],[Durée_Cumulée_Panne_Heure]]<=12),AND(Clients[[#This Row],[Ancienneté_Année]]<5,Clients[[#This Row],[Type_Forfait]]="Premium 5G 150Go")),"45%",IF(Clients[[#This Row],[Type_Forfait]]="Pro Monde","10%","0%"))) -> 45% | I7: =Clients[[#This Row],[Facture_Mensuelle]]*Clients[[#This Row],[Remise]] -> 9.5265
A8: CLI-00028 | B8: Kwilu | C8: Pro Monde | D8: 33.74 | E8: 2 | F8: 4 | G8: 5 | H8: =IF(AND(Clients[[#This Row],[Durée_Cumulée_Panne_Heure]]>12,Clients[[#This Row],[Ancienneté_Année]]>5),"70%",IF(OR(AND(Clients[[#This Row],[Durée_Cumulée_Panne_Heure]]>=4,Clients[[#This Row],[Durée_Cumulée_Panne_Heure]]<=12),AND(Clients[[#This Row],[Ancienneté_Année]]<5,Clients[[#This Row],[Type_Forfait]]="Premium 5G 150Go")),"45%",IF(Clients[[#This Row],[Type_Forfait]]="Pro Monde","10%","0%"))) -> 45% | I8: =Clients[[#This Row],[Facture_Mensuelle]]*Clients[[#This Row],[Remise]] -> 15.183
A9: CLI-00029 | B9: Bas-Uele | C9: Pro Monde | D9: 10.28 | E9: 10 | F9: 6 | G9: 0 | H9: =IF(AND(Clients[[#This Row],[Durée_Cumulée_Panne_Heure]]>12,Clients[[#This Row],[Ancienneté_Année]]>5),"70%",IF(OR(AND(Clients[[#This Row],[Durée_Cumulée_Panne_Heure]]>=4,Clients[[#This Row],[Durée_Cumulée_Panne_Heure]]<=12),AND(Clients[[#This Row],[Ancienneté_Année]]<5,Clients[[#This Row],[Type_Forfait]]="Premium 5G 150Go")),"45%",IF(Clients[[#This Row],[Type_Forfait]]="Pro Monde","10%","0%"))) -> 45% | I9: =Clients[[#This Row],[Facture_Mensuelle]]*Clients[[#This Row],[Remise]] -> 4.626
A10: CLI-00033 | B10: Tshuapa | C10: Premium 5G 150Go | D10: 71.9 | E10: 0 | F10: 3 | G10: 2 | H10: =IF(AND(Clients[[#This Row],[Durée_Cumulée_Panne_Heure]]>12,Clients[[#This Row],[Ancienneté_Année]]>5),"70%",IF(OR(AND(Clients[[#This Row],[Durée_Cumulée_Panne_Heure]]>=4,Clients[[#This Row],[Durée_Cumulée_Panne_Heure]]<=12),AND(Clients[[#This Row],[Ancienneté_Année]]<5,Clients[[#This Row],[Type_Forfait]]="Premium 5G 150Go")),"45%",IF(Clients[[#This Row],[Type_Forfait]]="Pro Monde","10%","0%"))) -> 45% | I10: =Clients[[#This Row],[Facture_Mensuelle]]*Clients[[#This Row],[Remise]] -> 32.355
A11: CLI-00034 | B11: Kongo-Central | C11: Bloqué 5Go | D11: 15.93 | E11: 2 | F11: 2 | G11: 4 | H11: =IF(AND(Clients[[#This Row],[Durée_Cumulée_Panne_Heure]]>12,Clients[[#This Row],[Ancienneté_Année]]>5),"70%",IF(OR(AND(Clients[[#This Row],[Durée_Cumulée_Panne_Heure]]>=4,Clients[[#This Row],[Durée_Cumulée_Panne_Heure]]<=12),AND(Clients[[#This Row],[Ancienneté_Année]]<5,Clients[[#This Row],[Type_Forfait]]="Premium 5G 150Go")),"45%",IF(Clients[[#This Row],[Type_Forfait]]="Pro Monde","10%","0%"))) -> 0% | I11: =Clients[[#This Row],[Facture_Mensuelle]]*Clients[[#This Row],[Remise]] -> 0
A12: CLI-00037 | B12: Tanganyika | C12: Premium 5G 150Go | D12: 11.15 | E12: 3 | F12: 6 | G12: 0 | H12: =IF(AND(Clients[[#This Row],[Durée_Cumulée_Panne_Heure]]>12,Clients[[#This Row],[Ancienneté_Année]]>5),"70%",IF(OR(AND(Clients[[#This Row],[Durée_Cumulée_Panne_Heure]]>=4,Clients[[#This Row],[Durée_Cumulée_Panne_Heure]]<=12),AND(Clients[[#This Row],[Ancienneté_Année]]<5,Clients[[#This Row],[Type_Forfait]]="Premium 5G 150Go")),"45%",IF(Clients[[#This Row],[Type_Forfait]]="Pro Monde","10%","0%"))) -> 45% | I12: =Clients[[#This Row],[Facture_Mensuelle]]*Clients[[#This Row],[Remise]] -> 5.0175
A13: CLI-00039 | B13: Maniema | C13: Pro Monde | D13: 21.27 | E13: 10 | F13: 1 | G13: 5 | H13: =IF(AND(Clients[[#This Row],[Durée_Cumulée_Panne_Heure]]>12,Clients[[#This Row],[Ancienneté_Année]]>5),"70%",IF(OR(AND(Clients[[#This Row],[Durée_Cumulée_Panne_Heure]]>=4,Clients[[#This Row],[Durée_Cumulée_Panne_Heure]]<=12),AND(Clients[[#This Row],[Ancienneté_Année]]<5,Clients[[#This Row],[Type_Forfait]]="Premium 5G 150Go")),"45%",IF(Clients[[#This Row],[Type_Forfait]]="Pro Monde","10%","0%"))) -> 10% | I13: =Clients[[#This Row],[Facture_Mensuelle]]*Clients[[#This Row],[Remise]] -> 2.127
... A751: CLI-01999 | B751: Sud-Ubangi | C751: Pro Monde | D751: 28.35 | E751: 4 | F751: 2 | G751: 1 | H751: =IF(AND(Clients[[#This Row],[Durée_Cumulée_Panne_Heure]]>12,Clients[[#This Row],[Ancienneté_Année]]>5),"70%",IF(OR(AND(Clients[[#This Row],[Durée_Cumulée_Panne_Heure]]>=4,Clients[[#This Row],[Durée_Cumulée_Panne_Heure]]<=12),AND(Clients[[#This Row],[Ancienneté_Année]]<5,Clients[[#This Row],[Type_Forfait]]="Premium 5G 150Go")),"45%",IF(Clients[[#This Row],[Type_Forfait]]="Pro Monde","10%","0%"))) -> 10% | I751: =Clients[[#This Row],[Facture_Mensuelle]]*Clients[[#This Row],[Remise]] -> 2.835
A752: TOTAL | D752: =SUM(D2:D751) -> 40865.54 | E752: =SUBTOTAL(109,Clients[Ancienneté_Année]) -> 3742 | F752: =SUBTOTAL(109,Clients[Durée_Cumulée_Panne_Heure]) -> 3037 | G752: =SUBTOTAL(109,Clients[Plaintes_Service_Client]) -> 1829 | I752: =SUBTOTAL(109,Clients[Perte_Financière]) -> 11659.466
